Workbook

Sheet Cover
I4: SHIPROCKET LIMITED
I5: #VALUE!
I15: Integrated Financial Model
I16: FY2024–FY2026 Historical | FY2027–FY2031 Forecast
J17: Industry: E-commerce Enablement / Logistics Technology
J19: By: Sneha Acharya
I21: Model Note: Historical financials are based on publicly available company filings. Forecasts represent analyst assumptions and are intended for academic/case-study purposes only.

Sheet Control Sheet
B2: Shiprocket
B3: Control Sheet
G5: Current Case | H5: 1
F8: Actual | I8: Explicit Forecast Period
B9: In INR million unless stated otherwise | F9: =G9-1 -> 2024 | G9: 2025 | H9: =G9+1 -> 2026 | I9: =H9+1 -> 2027 | J9: =I9+1 -> 2028 | K9: =J9+1 -> 2029 | L9: =K9+1 -> 2030 | M9: =L9+1 -> 2031
A11: # | B11: Revenue
B13: Revenue YoY % Growth
B14: Base Case | I14: 0.33 | J14: 0.36 | K14: 0.39 | L14: 0.42 | M14: 0.45
B15: Down Case | I15: 0.22 | J15: 0.22 | K15: 0.22 | L15: 0.22 | M15: 0.22
B16: ="Current Case - "& CHOOSE($H$5,$B$14,$B$15) -> Current Case - Base Case | I16: =CHOOSE($H$5,I14,I15) -> 0.33 | J16: =CHOOSE($H$5,J14,J15) -> 0.36 | K16: =CHOOSE($H$5,K14,K15) -> 0.39 | L16: =CHOOSE($H$5,L14,L15) -> 0.42 | M16: =CHOOSE($H$5,M14,M15) -> 0.45
B18: Core
B19: Base Case | I19: 0.2 | J19: 0.22 | K19: 0.24 | L19: 0.26 | M19: 0.28
B20: Down Case | I20: 0.15 | J20: 0.14 | K20: 0.13 | L20: 0.12 | M20: 0.11
B21: ="Current Case - "& CHOOSE($H$5,$B$14,$B$15) -> Current Case - Base Case | I21: =CHOOSE($H$5,I19,I20) -> 0.2 | J21: =CHOOSE($H$5,J19,J20) -> 0.22 | K21: =CHOOSE($H$5,K19,K20) -> 0.24 | L21: =CHOOSE($H$5,L19,L20) -> 0.26 | M21: =CHOOSE($H$5,M19,M20) -> 0.28
B23: Emerging
B24: Base Case | I24: 0.68 | J24: 0.65 | K24: 0.62 | L24: 0.6 | M24: 0.6
B25: Down Case | I25: 0.4 | J25: 0.39 | K25: 0.38 | L25: 0.37 | M25: 0.36
B26: ="Current Case - "& CHOOSE($H$5,$B$14,$B$15) -> Current Case - Base Case | I26: =CHOOSE($H$5,I24,I25) -> 0.68 | J26: =CHOOSE($H$5,J24,J25) -> 0.65 | K26: =CHOOSE($H$5,K24,K25) -> 0.62 | L26: =CHOOSE($H$5,L24,L25) -> 0.6 | M26: =CHOOSE($H$5,M24,M25) -> 0.6
B29: Selling, General and Administrative (SG&A) Expenses
B31: Cost of Merchant Solutions
B32: Base Case | I32: 0.675 | J32: 0.665 | K32: 0.655 | L32: 0.65 | M32: 0.65
B33: Down Case | I33: 0.8 | J33: 0.78 | K33: 0.76 | L33: 0.74 | M33: 0.72
B34: ="Current Case - "& CHOOSE($H$5,$B$14,$B$15) -> Current Case - Base Case | I34: =CHOOSE($H$5,I32,I33) -> 0.675 | J34: =CHOOSE($H$5,J32,J33) -> 0.665 | K34: =CHOOSE($H$5,K32,K33) -> 0.655 | L34: =CHOOSE($H$5,L32,L33) -> 0.65 | M34: =CHOOSE($H$5,M32,M33) -> 0.65
B36: Purchase of traded goods
B37: Base Case | I37: 0.01 | J37: 0.01 | K37: 0.01 | L37: 0.01 | M37: 0.01
B38: Down Case | I38: 0.05 | J38: 0.05 | K38: 0.05 | L38: 0.05 | M38: 0.05
B39: ="Current Case - "& CHOOSE($H$5,$B$14,$B$15) -> Current Case - Base Case | I39: =CHOOSE($H$5,I37,I38) -> 0.01 | J39: =CHOOSE($H$5,J37,J38) -> 0.01 | K39: =CHOOSE($H$5,K37,K38) -> 0.01 | L39: =CHOOSE($H$5,L37,L38) -> 0.01 | M39: =CHOOSE($H$5,M37,M38) -> 0.01
B41: Changes in inventories of traded goods
B42: Base Case | I42: 0 | J42: 0 | K42: 0 | L42: 0 | M42: 0
B43: Down Case | I43: 0 | J43: 0 | K43: 0 | L43: 0 | M43: 0
B44: ="Current Case - "& CHOOSE($H$5,$B$14,$B$15) -> Current Case - Base Case | I44: =CHOOSE($H$5,I42,I43) -> 0 | J44: =CHOOSE($H$5,J42,J43) -> 0 | K44: =CHOOSE($H$5,K42,K43) -> 0 | L44: =CHOOSE($H$5,L42,L43) -> 0 | M44: =CHOOSE($H$5,M42,M43) -> 0
B46: Employee Benefit Expenses
B47: Base Case | I47: 0.27 | J47: 0.27 | K47: 0.27 | L47: 0.27 | M47: 0.27
B48: Down Case | I48: 0.35 | J48: 0.35 | K48: 0.35 | L48: 0.35 | M48: 0.35
B49: ="Current Case - "& CHOOSE($H$5,$B$14,$B$15) -> Current Case - Base Case | I49: =CHOOSE($H$5,I47,I48) -> 0.27 | J49: =CHOOSE($H$5,J47,J48) -> 0.27 | K49: =CHOOSE($H$5,K47,K48) -> 0.27 | L49: =CHOOSE($H$5,L47,L48) -> 0.27 | M49: =CHOOSE($H$5,M47,M48) -> 0.27
B51: Other Expenses
B52: Base Case | I52: 0.11 | J52: 0.11 | K52: 0.11 | L52: 0.11 | M52: 0.11
B53: Down Case | I53: 0.2 | J53: 0.2 | K53: 0.2 | L53: 0.2 | M53: 0.2
B54: ="Current Case - "& CHOOSE($H$5,$B$14,$B$15) -> Current Case - Base Case | I54: =CHOOSE($H$5,I52,I53) -> 0.11 | J54: =CHOOSE($H$5,J52,J53) -> 0.11 | K54: =CHOOSE($H$5,K52,K53) -> 0.11 | L54: =CHOOSE($H$5,L52,L53) -> 0.11 | M54: =CHOOSE($H$5,M52,M53) -> 0.11
B56: Non Current Asset
...

Sheet Schedule Sheet
B2: ='Control Sheet'!B2 -> Shiprocket
B3: Schedule Sheet
F5: Current Case | G5: 0
D8: Actual | G8: Explicit Forecast Period
B9: In INR million unless stated otherwise | D9: 2024 | E9: 2025 | F9: =E9+1 -> 2026 | G9: =F9+1 -> 2027 | H9: =G9+1 -> 2028 | I9: =H9+1 -> 2029 | J9: =I9+1 -> 2030 | K9: =J9+1 -> 2031
B11: Sales Schedule
B13: Revenue | D13: ='Income Statement'!C9 -> 13159.76 | E13: ='Income Statement'!D9 -> 16320.12 | F13: ='Income Statement'!E9 -> 20241.41 | G13: =G15+G17 -> 26875.591 | H13: =H15+H17 -> 36680 | I13: =I15+I17 -> 51157.955 | J13: =J15+J17 -> 72684.433 | K13: =K15+K17 -> 105422.57
B14: Revenue Growth % | E14: =E13/D13-1 -> 0.24015332 | F14: =F13/E13-1 -> 0.24027336 | G14: ='Control Sheet'!I16 -> 0.33 | H14: ='Control Sheet'!J16 -> 0.36 | I14: ='Control Sheet'!K16 -> 0.39 | J14: ='Control Sheet'!L16 -> 0.42 | K14: ='Control Sheet'!M16 -> 0.45
B15: Core | D15: 10846.58 | E15: 13059.27 | F15: 14854.12 | G15: =F15*G16+(F15) -> 17824.944 | H15: =G15*H16+(G15) -> 21746.432 | I15: =H15*I16+(H15) -> 26965.575 | J15: =I15*J16+(I15) -> 33976.625 | K15: =J15*K16+(J15) -> 43490.08
E16: =E15/D15-1 -> 0.20399886 | F16: =F15/E15-1 -> 0.13743877 | G16: ='Control Sheet'!I21 -> 0.2 | H16: ='Control Sheet'!J21 -> 0.22 | I16: ='Control Sheet'!K21 -> 0.24 | J16: ='Control Sheet'!L21 -> 0.26 | K16: ='Control Sheet'!M21 -> 0.28
B17: Emerging | D17: 2313.18 | E17: 3260.85 | F17: 5387.29 | G17: =F17*G18+(F17) -> 9050.6472 | H17: =G17*H18+(G17) -> 14933.568 | I17: =H17*I18+(H17) -> 24192.38 | J17: =I17*J18+(I17) -> 38707.808 | K17: =J17*K18+(J17) -> 61932.493
E18: =E17/D17-1 -> 0.40968277 | F18: =F17/E17-1 -> 0.65211218 | G18: ='Control Sheet'!I26 -> 0.68 | H18: ='Control Sheet'!J26 -> 0.65 | I18: ='Control Sheet'!K26 -> 0.62 | J18: ='Control Sheet'!L26 -> 0.6 | K18: ='Control Sheet'!M26 -> 0.6
B20: SG&A (Excluding Depreciation and Interest Expenses) Schedule
B22: Cost of Merchant Solutions | D22: ='Income Statement'!C14 -> 10070.37 | E22: ='Income Statement'!D14 -> 12129.31 | F22: ='Income Statement'!E14 -> 14941.29 | G22: =G$13*G23 -> 18141.024 | H22: =H$13*H23 -> 24392.2 | I22: =I$13*I23 -> 33508.461 | J22: =J$13*J23 -> 47244.881 | K22: =K$13*K23 -> 68524.672
B23: Cost of Merchant Solutions % Revenue | D23: =D22/D$13 -> 0.76523964 | E23: =E22/E$13 -> 0.74321206 | F23: =F22/F$13 -> 0.7381546 | G23: ='Control Sheet'!I34 -> 0.675 | H23: ='Control Sheet'!J34 -> 0.665 | I23: ='Control Sheet'!K34 -> 0.655 | J23: ='Control Sheet'!L34 -> 0.65 | K23: ='Control Sheet'!M34 -> 0.65
B25: Purchase of traded goods | D25: ='Income Statement'!C15 -> 55.67 | E25: ='Income Statement'!D15 -> 79.67 | F25: ='Income Statement'!E15 -> 217.69 | G25: =G$13*G26 -> 268.75591 | H25: =H$13*H26 -> 366.8 | I25: =I$13*I26 -> 511.57955 | J25: =J$13*J26 -> 726.84433 | K25: =K$13*K26 -> 1054.2257
B26: Purchase of traded goods % Revenue | D26: =D25/D$13 -> 0.0042303203 | E26: =E25/E$13 -> 0.0048817043 | F26: =F25/F$13 -> 0.010754686 | G26: ='Control Sheet'!I39 -> 0.01 | H26: ='Control Sheet'!J39 -> 0.01 | I26: ='Control Sheet'!K39 -> 0.01 | J26: ='Control Sheet'!L39 -> 0.01 | K26: ='Control Sheet'!M39 -> 0.01
B28: Changes in inventories of traded goods | D28: ='Income Statement'!C16 -> -2.59 | E28: ='Income Statement'!D16 -> -2.28 | F28: ='Income Statement'!E16 -> -9.03 | G28: =G$13*G29 -> 0 | H28: =H$13*H29 -> 0 | I28: =I$13*I29 -> 0 | J28: =J$13*J29 -> 0 | K28: =K$13*K29 -> 0
B29: Changes in inventories of traded goods % Revenue | D29: =D28/D$13 -> -0.0001968121 | E29: =E28/E$13 -> -0.00013970486 | F29: =F28/F$13 -> -0.00044611517 | G29: ='Control Sheet'!I44 -> 0 | H29: ='Control Sheet'!J44 -> 0 | I29: ='Control Sheet'!K44 -> 0 | J29: ='Control Sheet'!L44 -> 0 | K29: ='Control Sheet'!M44 -> 0
B31: Employee Benefit Expenses | D31: ='Income Statement'!C17 -> 4307.91 | E31: ='Income Statement'!D17 -> 3149.16 | F31: ='Income Statement'!E17 -> 3794.77 | G31: =G$13*G32 -> 5375.1182 | H31: =H$13*H32 -> 7335.9999 | I31: =I$13*I32 -> 10231.591 | J31: =J$13*J32 -> 14536.887 | K31: =K$13*K32 -> 21084.515
B32: Employee Benefit Expenses % Revenue | D32: =D31/D$13 -> 0.32735475 | E32: =E31/E$13 -> 0.19296182 | F32: =F31/F$13 -> 0.18747558 | G32: 0.2 | H32: 0.2 | I32: 0.2 | J32: 0.2 | K32: 0.2
B34: Other Expenses | D34: ='Income Statement'!C20 -> 1660.07 | E34: ='Income Statement'!D20 -> 1563.95 | F34: ='Income Statement'!E20 -> 1962.02 | G34: =G$13*G35 -> 2687.5591 | H34: =H$13*H35 -> 3668 | I34: =I$13*I35 -> 5115.7955 | J34: =J$13*J35 -> 7268.4433 | K34: =K$13*K35 -> 10542.257
B35: Other Expenses % Revenue | D35: =D34/D$13 -> 0.12614744 | E35: =E34/E$13 -> 0.095829565 | F35: =F34/F$13 -> 0.096930994 | G35: 0.1 | H35: 0.1 | I35: 0.1 | J35: 0.1 | K35: 0.1
B37: Total SG&A | D37: =D22+D25+D28+D31+D34 -> 16091.43 | E37: =E22+E25+E28+E31+E34 -> 16919.81 | F37: =F22+F25+F28+F31+F34 -> 20906.74 | G37: =G22+G25+G28+G31+G34 -> 26472.457 | H37: =H22+H25+H28+H31+H34 -> 35763 | I37: =I22+I25+I28+I31+I34 -> 49367.427 | J37: =J22+J25+J28+J31+J34 -> 69777.055 | K37: =K22+K25+K28+K31+K34 -> 101205.67
B39: Non-Current Asset Schedule
B41: Opening PM&E | C41: 4 | G41: ='Balance Sheet'!E10 -> 245.04 | H41: =G44 -> 345.89693 | I41: =H44 -> 453.09795 | J41: =I44 -> 577.18364 | K41: =J44 -> 734.82302
B42: Add: Capex during the year | G42: =G13*G45 -> 268.75591 | H42: =H13*H45 -> 366.8 | I42: =I13*I45 -> 511.57955 | J42: =J13*J45 -> 726.84433 | K42: =K13*K45 -> 1054.2257
B43: Less: Depreciation | G43: =G77 -> 167.89898 | H43: =H77 -> 259.59898 | I43: =I77 -> 387.49387 | J43: =J77 -> 569.20495 | K43: =K77 -> 832.76138
B44: Closing PM&E | G44: =G41+G42-G43 -> 345.89693 | H44: =H41+H42-H43 -> 453.09795 | I44: =I41+I42-I43 -> 577.18364 | J44: =J41+J42-J43 -> 734.82302 | K44: =K41+K42-K43 -> 956.28737
G45: 0.01 | H45: 0.01 | I45: 0.01 | J45: 0.01 | K45: 0.01
B47: Right of use assets | C47: 5 | G47: ='Balance Sheet'!E13 -> 885.54 | H47: =G50 -> 846.25473 | I47: =H50 -> 831.65354 | J47: =I50 -> 859.516 | K47: =J50 -> 957.27437
B48: Addition during the year | G48: =G13*G51 -> 268.75591 | H48: =H13*H51 -> 366.8 | I48: =I13*I51 -> 511.57955 | J48: =J13*J51 -> 726.84433 | K48: =K13*K51 -> 1054.2257
B49: Less: Depreciation | G49: =G87 -> 308.04118 | H49: =H87 -> 381.40118 | I49: =I87 -> 483.71709 | J49: =J87 -> 629.08596 | K49: =K87 -> 839.9311
B50: Closing Right of use assets | G50: =G47+G48-G49 -> 846.25473 | H50: =H47+H48-H49 -> 831.65354 | I50: =I47+I48-I49 -> 859.516 | J50: =J47+J48-J49 -> 957.27437 | K50: =K47+K48-K49 -> 1171.569
G51: 0.01 | H51: 0.01 | I51: 0.01 | J51: 0.01 | K51: 0.01
B53: Intangible Non Current Asset - Amount Spend | C53: 4 | G53: ='Balance Sheet'!E12 -> 4.91 | H53: =G56 -> 17.096693 | I53: =H56 -> 29.917795 | J53: =I56 -> 44.427364 | K53: =J56 -> 62.292302
B54: Addition during the year | G54: =G13*G57 -> 26.875591 | H54: =H13*H57 -> 36.68 | I54: =I13*I57 -> 51.157955 | J54: =J13*J57 -> 72.684433 | K54: =K13*K57 -> 105.42257
B55: Less: Amortization | G55: =G97 -> 14.688898 | H55: =H97 -> 23.858898 | I55: =I97 -> 36.648387 | J55: =J97 -> 54.819495 | K55: =K97 -> 81.175138
B56: Closing Intangible Non-Current Asset | G56: =G53+G54-G55 -> 17.096693 | H56: =H53+H54-H55 -> 29.917795 | I56: =I53+I54-I55 -> 44.427364 | J56: =J53+J54-J55 -> 62.292302 | K56: =K53+K54-K55 -> 86.539737
G57: 0.001 | H57: 0.001 | I57: 0.001 | J57: 0.001 | K57: 0.001
...

Sheet 3 Statement Model
B2: ='Control Sheet'!B2 -> Shiprocket
B3: 3 Statement Model
G5: Current Case | H5: 0
M7: CAGR
D8: Actual | G8: Explicit Forecast Period | M8: 5 Years | N8: 3 Years
B9: In INR million unless stated otherwise | D9: 2024 | E9: =D9+1 -> 2025 | F9: =E9+1 -> 2026 | G9: =F9+1 -> 2027 | H9: =G9+1 -> 2028 | I9: =H9+1 -> 2029 | J9: =I9+1 -> 2030 | K9: =J9+1 -> 2031
B11: Income Statement
B13: Revenue | D13: ='Income Statement'!C9 -> 13159.76 | E13: ='Income Statement'!D9 -> 16320.12 | F13: ='Income Statement'!E9 -> 20241.41 | G13: ='Schedule Sheet'!G13 -> 26875.591 | H13: ='Schedule Sheet'!H13 -> 36680 | I13: ='Schedule Sheet'!I13 -> 51157.955 | J13: ='Schedule Sheet'!J13 -> 72684.433 | K13: ='Schedule Sheet'!K13 -> 105422.57 | M13: =IF(OR(F13<=0,K13<=0),"NM",_xlfn.RRI($K$9-$F$9,F13,K13)) -> 0.39103664 | N13: =IF(OR(H13<=0,K13<=0),"NM",_xlfn.RRI($K$9-$H$9,H13,K13)) -> 0.42178773
B14: Gross Profit | D14: =D13 -> 13159.76 | E14: =E13 -> 16320.12 | F14: =F13 -> 20241.41 | G14: =G13 -> 26875.591 | H14: =H13 -> 36680 | I14: =I13 -> 51157.955 | J14: =J13 -> 72684.433 | K14: =K13 -> 105422.57 | M14: =IF(OR(F14<=0,K14<=0),"NM",_xlfn.RRI($K$9-$F$9,F14,K14)) -> 0.39103664 | N14: =IF(OR(H14<=0,K14<=0),"NM",_xlfn.RRI($K$9-$H$9,H14,K14)) -> 0.42178773
B16: Less: SG&A (Excluding Depreciation and Amortization)
B17: Cost of Merchant Solutions | D17: ='Income Statement'!C14 -> 10070.37 | E17: ='Income Statement'!D14 -> 12129.31 | F17: ='Income Statement'!E14 -> 14941.29 | G17: ='Schedule Sheet'!G22 -> 18141.024 | H17: ='Schedule Sheet'!H22 -> 24392.2 | I17: ='Schedule Sheet'!I22 -> 33508.461 | J17: ='Schedule Sheet'!J22 -> 47244.881 | K17: ='Schedule Sheet'!K22 -> 68524.672 | M17: =IF(OR(F17<=0,K17<=0),"NM",_xlfn.RRI($K$9-$F$9,F17,K17)) -> 0.35610018 | N17: =IF(OR(H17<=0,K17<=0),"NM",_xlfn.RRI($K$9-$H$9,H17,K17)) -> 0.4110162
B18: Purchase of traded goods | D18: ='Income Statement'!C15 -> 55.67 | E18: ='Income Statement'!D15 -> 79.67 | F18: ='Income Statement'!E15 -> 217.69 | G18: ='Schedule Sheet'!G25 -> 268.75591 | H18: ='Schedule Sheet'!H25 -> 366.8 | I18: ='Schedule Sheet'!I25 -> 511.57955 | J18: ='Schedule Sheet'!J25 -> 726.84433 | K18: ='Schedule Sheet'!K25 -> 1054.2257 | M18: =IF(OR(F18<=0,K18<=0),"NM",_xlfn.RRI($K$9-$F$9,F18,K18)) -> 0.37094182 | N18: =IF(OR(H18<=0,K18<=0),"NM",_xlfn.RRI($K$9-$H$9,H18,K18)) -> 0.42178773
B19: Changes in inventories of traded goods | D19: ='Income Statement'!C16 -> -2.59 | E19: ='Income Statement'!D16 -> -2.28 | F19: ='Income Statement'!E16 -> -9.03 | G19: ='Schedule Sheet'!G28 -> 0 | H19: ='Schedule Sheet'!H28 -> 0 | I19: ='Schedule Sheet'!I28 -> 0 | J19: ='Schedule Sheet'!J28 -> 0 | K19: ='Schedule Sheet'!K28 -> 0 | M19: =IF(OR(F19<=0,K19<=0),"NM",_xlfn.RRI($K$9-$F$9,F19,K19)) -> NM | N19: =IF(OR(H19<=0,K19<=0),"NM",_xlfn.RRI($K$9-$H$9,H19,K19)) -> NM
B20: Employee Benefit Expenses | D20: ='Income Statement'!C17 -> 4307.91 | E20: ='Income Statement'!D17 -> 3149.16 | F20: ='Income Statement'!E17 -> 3794.77 | G20: ='Schedule Sheet'!G31 -> 5375.1182 | H20: ='Schedule Sheet'!H31 -> 7335.9999 | I20: ='Schedule Sheet'!I31 -> 10231.591 | J20: ='Schedule Sheet'!J31 -> 14536.887 | K20: ='Schedule Sheet'!K31 -> 21084.515 | M20: =IF(OR(F20<=0,K20<=0),"NM",_xlfn.RRI($K$9-$F$9,F20,K20)) -> 0.40914482 | N20: =IF(OR(H20<=0,K20<=0),"NM",_xlfn.RRI($K$9-$H$9,H20,K20)) -> 0.42178773
B21: Other Expenses | D21: ='Income Statement'!C20 -> 1660.07 | E21: ='Income Statement'!D20 -> 1563.95 | F21: ='Income Statement'!E20 -> 1962.02 | G21: ='Schedule Sheet'!G34 -> 2687.5591 | H21: ='Schedule Sheet'!H34 -> 3668 | I21: ='Schedule Sheet'!I34 -> 5115.7955 | J21: ='Schedule Sheet'!J34 -> 7268.4433 | K21: ='Schedule Sheet'!K34 -> 10542.257 | M21: =IF(OR(F21<=0,K21<=0),"NM",_xlfn.RRI($K$9-$F$9,F21,K21)) -> 0.39973569 | N21: =IF(OR(H21<=0,K21<=0),"NM",_xlfn.RRI($K$9-$H$9,H21,K21)) -> 0.42178773
B23: Total SG&A | D23: =SUM(D17:D21) -> 16091.43 | E23: =SUM(E17:E21) -> 16919.81 | F23: =SUM(F17:F21) -> 20906.74 | G23: =SUM(G17:G21) -> 26472.457 | H23: =SUM(H17:H21) -> 35763 | I23: =SUM(I17:I21) -> 49367.427 | J23: =SUM(J17:J21) -> 69777.055 | K23: =SUM(K17:K21) -> 101205.67 | M23: =IF(OR(F23<=0,K23<=0),"NM",_xlfn.RRI($K$9-$F$9,F23,K23)) -> 0.37083033 | N23: =IF(OR(H23<=0,K23<=0),"NM",_xlfn.RRI($K$9-$H$9,H23,K23)) -> 0.4144588
B24: EBITDA | D24: =D14-D23 -> -2931.67 | E24: =E14-E23 -> -599.69 | F24: =F14-F23 -> -665.33 | G24: =G14-G23 -> 403.13387 | H24: =H14-H23 -> 916.99999 | I24: =I14-I23 -> 1790.5284 | J24: =J14-J23 -> 2907.3773 | K24: =K14-K23 -> 4216.9029
B26: EBITDA Margin | D26: =D24/D13 -> -0.22277534 | E26: =E24/E13 -> -0.036745441 | F26: =F24/F13 -> -0.032869746 | G26: =G24/G13 -> 0.015 | H26: =H24/H13 -> 0.025 | I26: =I24/I13 -> 0.035 | J26: =J24/J13 -> 0.04 | K26: =K24/K13 -> 0.04
B28: Less: Depreciation and Amortization
B29: Depreciation | D29: ='Income Statement'!C19 -> 759.78 | E29: ='Income Statement'!D19 -> 352.2 | F29: ='Income Statement'!E19 -> 362.97 | G29: ='Schedule Sheet'!G77+'Schedule Sheet'!G87+'Schedule Sheet'!G97 -> 490.62906 | H29: ='Schedule Sheet'!H77+'Schedule Sheet'!H87+'Schedule Sheet'!H97 -> 664.85906 | I29: ='Schedule Sheet'!I77+'Schedule Sheet'!I87+'Schedule Sheet'!I97 -> 907.85934 | J29: ='Schedule Sheet'!J77+'Schedule Sheet'!J87+'Schedule Sheet'!J97 -> 1253.1104 | K29: ='Schedule Sheet'!K77+'Schedule Sheet'!K87+'Schedule Sheet'!K97 -> 1753.8676 | M29: =_xlfn.RRI($K$9-$F$9,F29,K29) -> 0.37033016 | N29: =_xlfn.RRI($K$9-$H$9,H29,K29) -> 0.38172752
B30: EBIT | D30: =D24-D29 -> -3691.45 | E30: =E24-E29 -> -951.89 | F30: =F24-F29 -> -1028.3 | G30: =G24-G29 -> -87.49519 | H30: =H24-H29 -> 252.14093 | I30: =I24-I29 -> 882.66909 | J30: =J24-J29 -> 1654.2669 | K30: =K24-K29 -> 2463.0353 | M30: =IF(OR(F30<=0,K30<=0),"NM",_xlfn.RRI($K$9-$F$9,F30,K30)) -> NM | N30: =IF(OR(H30<=0,K30<=0),"NM",_xlfn.RRI($K$9-$H$9,H30,K30)) -> 1.1376787
B32: Less: Interest Expenses
B33: Finance Cost | D33: ='Income Statement'!C18 -> 233.14 | E33: ='Income Statement'!D18 -> 220.69 | F33: ='Income Statement'!E18 -> 263.93 | G33: ='Schedule Sheet'!G201+'Schedule Sheet'!G203 -> 403.13387 | H33: ='Schedule Sheet'!H201+'Schedule Sheet'!H203 -> 550.19999 | I33: ='Schedule Sheet'!I201+'Schedule Sheet'!I203 -> 767.36933 | J33: ='Schedule Sheet'!J201+'Schedule Sheet'!J203 -> 1090.2665 | K33: ='Schedule Sheet'!K201+'Schedule Sheet'!K203 -> 1581.3386 | M33: =IF(OR(F33<=0,K33<=0),"NM",_xlfn.RRI($K$9-$F$9,F33,K33)) -> 0.43056377 | N33: =IF(OR(H33<=0,K33<=0),"NM",_xlfn.RRI($K$9-$H$9,H33,K33)) -> 0.42178773
B34: Exceptional items | D34: ='Income Statement'!C23 -> -2443.79 | E34: ='Income Statement'!D23 -> 0 | F34: ='Income Statement'!E23 -> -33.02 | G34: ='Schedule Sheet'!G208 -> 0 | H34: ='Schedule Sheet'!H208 -> 0 | I34: ='Schedule Sheet'!I208 -> 0 | J34: ='Schedule Sheet'!J208 -> 0 | K34: ='Schedule Sheet'!K208 -> 0
B35: Add: Other Income | D35: ='Income Statement'!C10 -> 418.57 | E35: ='Income Statement'!D10 -> 428.09 | F35: ='Income Statement'!E10 -> 532.8 | G35: ='Schedule Sheet'!G213 -> 806.26774 | H35: ='Schedule Sheet'!H213 -> 1100.4 | I35: ='Schedule Sheet'!I213 -> 1534.7387 | J35: ='Schedule Sheet'!J213 -> 2180.533 | K35: ='Schedule Sheet'!K213 -> 3162.6772 | M35: =IF(OR(F35<=0,K35<=0),"NM",_xlfn.RRI($K$9-$F$9,F35,K35)) -> 0.4279011 | N35: =IF(OR(H35<=0,K35<=0),"NM",_xlfn.RRI($K$9-$H$9,H35,K35)) -> 0.42178773
B36: EBT | D36: =D30-D33+D34+D35 -> -5949.81 | E36: =E30-E33+E34+E35 -> -744.49 | F36: =F30-F33+F34+F35 -> -792.45 | G36: =G30-G33+G34+G35 -> 315.63868 | H36: =H30-H33+H34+H35 -> 802.34093 | I36: =I30-I33+I34+I35 -> 1650.0384 | J36: =J30-J33+J34+J35 -> 2744.5334 | K36: =K30-K33+K34+K35 -> 4044.3739 | M36: =IF(OR(F36<=0,K36<=0),"NM",_xlfn.RRI($K$9-$F$9,F36,K36)) -> NM | N36: =IF(OR(H36<=0,K36<=0),"NM",_xlfn.RRI($K$9-$H$9,H36,K36)) -> 0.71460512
B38: Less: Taxes | D38: ='Income Statement'!C31 -> 0 | E38: ='Income Statement'!D31 -> 0 | F38: ='Income Statement'!E31 -> 0 | G38: ='Schedule Sheet'!G106 -> 0 | H38: ='Schedule Sheet'!H106 -> 246.43523 | I38: ='Schedule Sheet'!I106 -> 476.45705 | J38: ='Schedule Sheet'!J106 -> 776.98889 | K38: ='Schedule Sheet'!K106 -> 1142.8717 | M38: =IF(OR(F38<=0,K38<=0),"NM",_xlfn.RRI($K$9-$F$9,F38,K38)) -> NM | N38: =_xlfn.RRI($K$9-$H$9,H38,K38) -> 0.66762434
B39: Net Income | D39: =D36+D38 -> -5949.81 | E39: =E36+E38 -> -744.49 | F39: =F36+F38 -> -792.45 | G39: =G36-G38 -> 315.63868 | H39: =H36-H38 -> 555.9057 | I39: =I36-I38 -> 1173.5814 | J39: =J36-J38 -> 1967.5445 | K39: =K36-K38 -> 2901.5022 | M39: =IF(OR(F39<=0,K39<=0),"NM",_xlfn.RRI($K$9-$F$9,F39,K39)) -> NM | N39: =IF(OR(H39<=0,K39<=0),"NM",_xlfn.RRI($K$9-$H$9,H39,K39)) -> 0.73463162
B41: Balance Sheet
B43: Assets
B44: Cash | D44: ='Balance Sheet'!C26 -> 842.96 | E44: ='Balance Sheet'!D26 -> 1264.4 | F44: ='Balance Sheet'!E26 -> 1847.43 | G44: =G207 -> 2691.4509 | H44: =H207 -> 3596.9711 | I44: =I207 -> 4963.7269 | J44: =J207 -> 6988.752 | K44: =K207 -> 9203.7861
B45: Bank balances other than cash and cash equivalents, above | D45: ='Balance Sheet'!C27 -> 1687.75 | E45: ='Balance Sheet'!D27 -> 3753.08 | F45: ='Balance Sheet'!E27 -> 34.02 | G45: =F45 -> 34.02 | H45: =G45 -> 34.02 | I45: =H45 -> 34.02 | J45: =I45 -> 34.02 | K45: =J45 -> 34.02
B46: Inventory | D46: ='Balance Sheet'!C22 -> 14.72 | E46: ='Balance Sheet'!D22 -> 17 | F46: ='Balance Sheet'!E22 -> 26.03 | G46: ='Schedule Sheet'!G129 -> 36.815878 | H46: ='Schedule Sheet'!G129 -> 36.815878 | I46: ='Schedule Sheet'!H129 -> 50.246575 | J46: ='Schedule Sheet'!I129 -> 70.079391 | K46: ='Schedule Sheet'!J129 -> 99.567716
B47: Trade Receivables | D47: ='Balance Sheet'!C25 -> 1170.59 | E47: ='Balance Sheet'!D25 -> 1470.26 | F47: ='Balance Sheet'!E25 -> 2364.95 | G47: ='Schedule Sheet'!G124 -> 3681.5878 | H47: ='Schedule Sheet'!G124 -> 3681.5878 | I47: ='Schedule Sheet'!H124 -> 4321.2054 | J47: ='Schedule Sheet'!I124 -> 5746.51 | K47: ='Schedule Sheet'!J124 -> 7965.4173
B48: Financial Current Assets | D48: ='Balance Sheet'!C24+'Balance Sheet'!C28 -> 145.92 | E48: ='Balance Sheet'!D24+'Balance Sheet'!D28 -> 517.63 | F48: ='Balance Sheet'!E24+'Balance Sheet'!E28 -> 300 | G48: ='Schedule Sheet'!G178 -> 268.75591 | H48: ='Schedule Sheet'!H178 -> 366.8 | I48: ='Schedule Sheet'!I178 -> 511.57955 | J48: ='Schedule Sheet'!J178 -> 726.84433 | K48: ='Schedule Sheet'!K178 -> 1054.2257
B49: Other | D49: ='Balance Sheet'!C29 -> 2293.56 | E49: ='Balance Sheet'!D29 -> 4181.15 | F49: ='Balance Sheet'!E29 -> 3730.6 | G49: ='Schedule Sheet'!G134 -> 4031.3387 | H49: ='Schedule Sheet'!H134+74.6243023095594 -> 4476.2242 | I49: ='Schedule Sheet'!I134 -> 5115.7955 | J49: ='Schedule Sheet'!J134 -> 5814.7546 | K49: ='Schedule Sheet'!K134+22.7329044755752 -> 6348.0873
B50: Current tax assets (net) | D50: ='Balance Sheet'!C30 -> 307.85 | E50: ='Balance Sheet'!D30 -> 241.51 | F50: ='Balance Sheet'!E30 -> 421.38 | G50: =F50 -> 421.38 | H50: =G50 -> 421.38 | I50: =H50 -> 421.38 | J50: =I50 -> 421.38 | K50: =J50 -> 421.38
B51: Other Current Assets | D51: ='Balance Sheet'!C31 -> 558.28 | E51: ='Balance Sheet'!D31 -> 1101.21 | F51: ='Balance Sheet'!E31 -> 1441.21 | G51: ='Schedule Sheet'!G139 -> 1612.5355 | H51: ='Schedule Sheet'!H139 -> 2200.8 | I51: ='Schedule Sheet'!I139 -> 2557.8978 | J51: ='Schedule Sheet'!J139 -> 2907.3773 | K51: ='Schedule Sheet'!K139 -> 3162.6772
B52: Total Current Assests | D52: =SUM(D44:D51) -> 7021.63 | E52: =SUM(E44:E51) -> 12546.24 | F52: =SUM(F44:F51) -> 10165.62 | G52: =SUM(G44:G51) -> 12777.885 | H52: =SUM(H44:H51) -> 14814.599 | I52: =SUM(I44:I51) -> 17975.852 | J52: =SUM(J44:J51) -> 22709.718 | K52: =SUM(K44:K51) -> 28289.161
B54: Plant, Machinery and Equipment | D54: ='Balance Sheet'!C10 -> 267.57 | E54: ='Balance Sheet'!D10 -> 169.06 | F54: ='Balance Sheet'!E10 -> 245.04 | G54: ='Schedule Sheet'!G44 -> 345.89693 | H54: ='Schedule Sheet'!H44 -> 453.09795 | I54: ='Schedule Sheet'!I44 -> 577.18364 | J54: ='Schedule Sheet'!J44 -> 734.82302 | K54: ='Schedule Sheet'!K44 -> 956.28737
...

Sheet Ratio Analysis
B2: ='Control Sheet'!B2 -> Shiprocket
B3: Ratio Analysis
E5: Current Case | F5: 1
D8: Actual | E8: Actual | H8: Explicit Forecast Period
B9: In INR million unless stated otherwise | E9: 2024 | F9: =E9+1 -> 2025 | G9: =F9+1 -> 2026 | H9: =G9+1 -> 2027 | I9: =H9+1 -> 2028 | J9: =I9+1 -> 2029 | K9: =J9+1 -> 2030 | L9: =K9+1 -> 2031
B11: Liquidity Ratio
B13: Current Assets | E13: ='3 Statement Model'!D52 -> 7021.63 | F13: ='3 Statement Model'!E52 -> 12546.24 | G13: ='3 Statement Model'!F52 -> 10165.62 | H13: ='3 Statement Model'!G52 -> 12777.885 | I13: ='3 Statement Model'!H52 -> 14814.599 | J13: ='3 Statement Model'!I52 -> 17975.852 | K13: ='3 Statement Model'!J52 -> 22709.718 | L13: ='3 Statement Model'!K52 -> 28289.161
B14: Current Liability | E14: ='3 Statement Model'!D72 -> 6751.6 | F14: ='3 Statement Model'!E72 -> 7356.53 | G14: ='3 Statement Model'!F72 -> 8928.42 | H14: ='3 Statement Model'!G72 -> 11644.862 | I14: ='3 Statement Model'!H72 -> 14180.086 | J14: ='3 Statement Model'!I72 -> 17643.888 | K14: ='3 Statement Model'!J72 -> 22037.323 | L14: ='3 Statement Model'!K72 -> 27251.013
B15: Liquidity Ratio | E15: =E13/E14 -> 1.039995 | F15: =F13/F14 -> 1.7054562 | G15: =G13/G14 -> 1.1385688 | H15: =H13/H14 -> 1.097298 | I15: =I13/I14 -> 1.0447468 | J15: =J13/J14 -> 1.0188146 | K15: =K13/K14 -> 1.0305117 | L15: =L13/L14 -> 1.0380958
B17: Current Assets | E17: ='3 Statement Model'!D52 -> 7021.63 | F17: ='3 Statement Model'!E52 -> 12546.24 | G17: ='3 Statement Model'!F52 -> 10165.62 | H17: ='3 Statement Model'!G52 -> 12777.885 | I17: ='3 Statement Model'!H52 -> 14814.599 | J17: ='3 Statement Model'!I52 -> 17975.852 | K17: ='3 Statement Model'!J52 -> 22709.718 | L17: ='3 Statement Model'!K52 -> 28289.161
B18: Inventory | E18: ='3 Statement Model'!D46 -> 14.72 | F18: ='3 Statement Model'!E46 -> 17 | G18: ='3 Statement Model'!F46 -> 26.03 | H18: ='3 Statement Model'!G46 -> 36.815878 | I18: ='3 Statement Model'!H46 -> 36.815878 | J18: ='3 Statement Model'!I46 -> 50.246575 | K18: ='3 Statement Model'!J46 -> 70.079391 | L18: ='3 Statement Model'!K46 -> 99.567716
B19: Current Liability | E19: ='3 Statement Model'!D72 -> 6751.6 | F19: ='3 Statement Model'!E72 -> 7356.53 | G19: ='3 Statement Model'!F72 -> 8928.42 | H19: ='3 Statement Model'!G72 -> 11644.862 | I19: ='3 Statement Model'!H72 -> 14180.086 | J19: ='3 Statement Model'!I72 -> 17643.888 | K19: ='3 Statement Model'!J72 -> 22037.323 | L19: ='3 Statement Model'!K72 -> 27251.013
B20: Quick Ratio (Acid Ratio) | E20: =(E17-E18)/E19 -> 1.0378147 | F20: =(F17-F18)/F19 -> 1.7031454 | G20: =(G17-G18)/G19 -> 1.1356533 | H20: =(H17-H18)/H19 -> 1.0941365 | I20: =(I17-I18)/I19 -> 1.0421505 | J20: =(J17-J18)/J19 -> 1.0159668 | K20: =(K17-K18)/K19 -> 1.0273316 | L20: =(L17-L18)/L19 -> 1.034442
B22: Inventory Days | E22: ='Schedule Sheet'!D130 -> 0.40827492 | F22: ='Schedule Sheet'!E130 -> 0.38020554 | G22: ='Schedule Sheet'!F130 -> 0.46938183 | H22: ='Schedule Sheet'!G130 -> 0.5 | I22: ='Schedule Sheet'!H130 -> 0.5 | J22: ='Schedule Sheet'!I130 -> 0.5 | K22: ='Schedule Sheet'!J130 -> 0.5 | L22: ='Schedule Sheet'!K130 -> 0.5
B23: Debtor Days | E23: ='Schedule Sheet'!D125 -> 32.467564 | F23: ='Schedule Sheet'!E125 -> 32.882411 | G23: ='Schedule Sheet'!F125 -> 42.645584 | H23: ='Schedule Sheet'!G125 -> 50 | I23: ='Schedule Sheet'!H125 -> 43 | J23: ='Schedule Sheet'!I125 -> 41 | K23: ='Schedule Sheet'!J125 -> 40 | L23: ='Schedule Sheet'!K125 -> 40
B24: Creditor Days | E24: ='Schedule Sheet'!D145 -> 56.033514 | F24: ='Schedule Sheet'!E145 -> 51.304264 | G24: ='Schedule Sheet'!F145 -> 49.077179 | H24: ='Schedule Sheet'!G145 -> 45 | I24: ='Schedule Sheet'!H145 -> 40 | J24: ='Schedule Sheet'!I145 -> 35 | K24: ='Schedule Sheet'!J145 -> 30 | L24: ='Schedule Sheet'!K145 -> 25
B25: Cash Conversion Days | E25: =E22+E23-E24 -> -23.157675 | F25: =F22+F23-F24 -> -18.041647 | G25: =G22+G23-G24 -> -5.9622131 | H25: =H22+H23-H24 -> 5.5 | I25: =I22+I23-I24 -> 3.5 | J25: =J22+J23-J24 -> 6.5 | K25: =K22+K23-K24 -> 10.5 | L25: =L22+L23-L24 -> 15.5
B27: Leverage Ratios (Solvency Ratios)
B29: Total Debt | E29: ='3 Statement Model'!D70+'3 Statement Model'!D69+'3 Statement Model'!D74 -> 3159.15 | F29: ='3 Statement Model'!E70+'3 Statement Model'!E69+'3 Statement Model'!E74 -> 3346.17 | G29: ='3 Statement Model'!F70+'3 Statement Model'!F69+'3 Statement Model'!F74 -> 3447.85 | H29: ='3 Statement Model'!G70+'3 Statement Model'!G69+'3 Statement Model'!G74 -> 4583.8935 | I29: ='3 Statement Model'!H70+'3 Statement Model'!H69+'3 Statement Model'!H74 -> 5868.7999 | J29: ='3 Statement Model'!I70+'3 Statement Model'!I69+'3 Statement Model'!I74 -> 7211.8419 | K29: ='3 Statement Model'!J70+'3 Statement Model'!J69+'3 Statement Model'!J74 -> 8859.863 | L29: ='3 Statement Model'!K70+'3 Statement Model'!K69+'3 Statement Model'!K74 -> 11596.483
B30: Total Equity | E30: ='3 Statement Model'!D78+'3 Statement Model'!D80+'3 Statement Model'!D79 -> 12861.77 | F30: ='3 Statement Model'!E78+'3 Statement Model'!E80+'3 Statement Model'!E79 -> 14912.51 | G30: ='3 Statement Model'!F78+'3 Statement Model'!F80+'3 Statement Model'!F79 -> 15243.11 | H30: ='3 Statement Model'!G78+'3 Statement Model'!G80+'3 Statement Model'!G79 -> 15558.749 | I30: ='3 Statement Model'!H78+'3 Statement Model'!H80+'3 Statement Model'!H79 -> 16114.654 | J30: ='3 Statement Model'!I78+'3 Statement Model'!I80+'3 Statement Model'!I79 -> 17288.236 | K30: ='3 Statement Model'!J78+'3 Statement Model'!J80+'3 Statement Model'!J79 -> 19255.78 | L30: ='3 Statement Model'!K78+'3 Statement Model'!K80+'3 Statement Model'!K79 -> 22157.282
B31: Debt to Equity | E31: =E29/E30 -> 0.24562327 | F31: =F29/F30 -> 0.22438677 | G31: =G29/G30 -> 0.22619072 | H31: =H29/H30 -> 0.29461839 | I31: =I29/I30 -> 0.36419025 | J31: =J29/J30 -> 0.41715314 | K31: =K29/K30 -> 0.46011446 | L31: =L29/L30 -> 0.52337118
B33: Total Debt | E33: =E29 -> 3159.15 | F33: =F29 -> 3346.17 | G33: =G29 -> 3447.85 | H33: =H29 -> 4583.8935 | I33: =I29 -> 5868.7999 | J33: =J29 -> 7211.8419 | K33: =K29 -> 8859.863 | L33: =L29 -> 11596.483
B34: Total Assets | E34: ='3 Statement Model'!D62 -> 20512.18 | F34: ='3 Statement Model'!E62 -> 23086.22 | G34: ='3 Statement Model'!F62 -> 25047.68 | H34: ='3 Statement Model'!G62 -> 28696.812 | I34: ='3 Statement Model'!H62 -> 32495.54 | J34: ='3 Statement Model'!I62 -> 38153.645 | K34: ='3 Statement Model'!J62 -> 45719.215 | L34: ='3 Statement Model'!K62 -> 57209.566
B35: Debt to Assets Ratio | E35: =E33/E34 -> 0.15401337 | F35: =F33/F34 -> 0.14494231 | G35: =G33/G34 -> 0.13765147 | H35: =H33/H34 -> 0.15973529 | I35: =I33/I34 -> 0.18060324 | J35: =J33/J34 -> 0.18902104 | K35: =K33/K34 -> 0.19378861 | L35: =L33/L34 -> 0.20270182
B37: Total Equity | E37: =E30 -> 12861.77 | F37: =F30 -> 14912.51 | G37: =G30 -> 15243.11 | H37: =H30 -> 15558.749 | I37: =I30 -> 16114.654 | J37: =J30 -> 17288.236 | K37: =K30 -> 19255.78 | L37: =L30 -> 22157.282
B38: Total Assets | E38: =E34 -> 20512.18 | F38: =F34 -> 23086.22 | G38: =G34 -> 25047.68 | H38: =H34 -> 28696.812 | I38: =I34 -> 32495.54 | J38: =J34 -> 38153.645 | K38: =K34 -> 45719.215 | L38: =L34 -> 57209.566
B39: Equity Ratio | E39: =E37/E38 -> 0.62703087 | F39: =F37/F38 -> 0.64594854 | G39: =G37/G38 -> 0.60856375 | H39: =H37/H38 -> 0.54217691 | I39: =I37/I38 -> 0.49590357 | J39: =J37/J38 -> 0.45312147 | K39: =K37/K38 -> 0.42117477 | L39: =L37/L38 -> 0.38730031
B41: Profitability/Margin Ratios
B43: Gross Profit | E43: ='3 Statement Model'!D14 -> 13159.76 | F43: ='3 Statement Model'!E14 -> 16320.12 | G43: ='3 Statement Model'!F14 -> 20241.41 | H43: ='3 Statement Model'!G14 -> 26875.591 | I43: ='3 Statement Model'!H14 -> 36680 | J43: ='3 Statement Model'!I14 -> 51157.955 | K43: ='3 Statement Model'!J14 -> 72684.433 | L43: ='3 Statement Model'!K14 -> 105422.57
B44: Total Sales | E44: ='3 Statement Model'!D13 -> 13159.76 | F44: ='3 Statement Model'!E13 -> 16320.12 | G44: ='3 Statement Model'!F13 -> 20241.41 | H44: ='3 Statement Model'!G13 -> 26875.591 | I44: ='3 Statement Model'!H13 -> 36680 | J44: ='3 Statement Model'!I13 -> 51157.955 | K44: ='3 Statement Model'!J13 -> 72684.433 | L44: ='3 Statement Model'!K13 -> 105422.57
B45: Gross Margin Ratios | E45: =E43/E44 -> 1 | F45: =F43/F44 -> 1 | G45: =G43/G44 -> 1 | H45: =H43/H44 -> 1 | I45: =I43/I44 -> 1 | J45: =J43/J44 -> 1 | K45: =K43/K44 -> 1 | L45: =L43/L44 -> 1
B47: EBITDA | E47: ='3 Statement Model'!D24 -> -2931.67 | F47: ='3 Statement Model'!E24 -> -599.69 | G47: ='3 Statement Model'!F24 -> -665.33 | H47: ='3 Statement Model'!G24 -> 403.13387 | I47: ='3 Statement Model'!H24 -> 916.99999 | J47: ='3 Statement Model'!I24 -> 1790.5284 | K47: ='3 Statement Model'!J24 -> 2907.3773 | L47: ='3 Statement Model'!K24 -> 4216.9029
B48: Total Sales | E48: =E44 -> 13159.76 | F48: =F44 -> 16320.12 | G48: =G44 -> 20241.41 | H48: =H44 -> 26875.591 | I48: =I44 -> 36680 | J48: =J44 -> 51157.955 | K48: =K44 -> 72684.433 | L48: =L44 -> 105422.57
B49: EBITDA Margin Ratios | E49: =E47/E48 -> -0.22277534 | F49: =F47/F48 -> -0.036745441 | G49: =G47/G48 -> -0.032869746 | H49: =H47/H48 -> 0.015 | I49: =I47/I48 -> 0.025 | J49: =J47/J48 -> 0.035 | K49: =K47/K48 -> 0.04 | L49: =L47/L48 -> 0.04
B51: EBIT | E51: ='3 Statement Model'!D30 -> -3691.45 | F51: ='3 Statement Model'!E30 -> -951.89 | G51: ='3 Statement Model'!F30 -> -1028.3 | H51: ='3 Statement Model'!G30 -> -87.49519 | I51: ='3 Statement Model'!H30 -> 252.14093 | J51: ='3 Statement Model'!I30 -> 882.66909 | K51: ='3 Statement Model'!J30 -> 1654.2669 | L51: ='3 Statement Model'!K30 -> 2463.0353
B52: Total Sales | E52: =E48 -> 13159.76 | F52: =F48 -> 16320.12 | G52: =G48 -> 20241.41 | H52: =H48 -> 26875.591 | I52: =I48 -> 36680 | J52: =J48 -> 51157.955 | K52: =K48 -> 72684.433 | L52: =L48 -> 105422.57
B53: EBIT Margin Ratios | E53: =E51/E52 -> -0.28051043 | F53: =F51/F52 -> -0.058326164 | G53: =G51/G52 -> -0.050801797 | H53: =H51/H52 -> -0.0032555634 | I53: =I51/I52 -> 0.0068740713 | J53: =J51/J52 -> 0.017253799 | K53: =K51/K52 -> 0.022759577 | L53: =L51/L52 -> 0.023363453
B55: Net Income | E55: ='3 Statement Model'!D39 -> -5949.81 | F55: ='3 Statement Model'!E39 -> -744.49 | G55: ='3 Statement Model'!F39 -> -792.45 | H55: ='3 Statement Model'!G39 -> 315.63868 | I55: ='3 Statement Model'!H39 -> 555.9057 | J55: ='3 Statement Model'!I39 -> 1173.5814 | K55: ='3 Statement Model'!J39 -> 1967.5445 | L55: ='3 Statement Model'!K39 -> 2901.5022
B56: Total Sales | E56: =E52 -> 13159.76 | F56: =F52 -> 16320.12 | G56: =G52 -> 20241.41 | H56: =H52 -> 26875.591 | I56: =I52 -> 36680 | J56: =J52 -> 51157.955 | K56: =K52 -> 72684.433 | L56: =L52 -> 105422.57
B57: Net Profit Margin | E57: =E55/E56 -> -0.45212147 | F57: =F55/F56 -> -0.045617924 | G57: =G55/G56 -> -0.039149941 | H57: =H55/H56 -> 0.011744437 | I57: =I55/I56 -> 0.015155553 | J57: =J55/J56 -> 0.022940349 | K57: =K55/K56 -> 0.027069682 | L57: =L55/L56 -> 0.027522589
...

Sheet Balance Sheet
B2: ='Control Sheet'!B2 -> Shiprocket
B3: Balance Sheet
B4: In INR million unless stated otherwise
B6: Particulars | C6: 2024 | D6: =C6+1 -> 2025 | E6: =D6+1 -> 2026
B8: ASSETS
B9: Non-current assets
B10: Property, plant and equipment | C10: 267.57 | D10: 169.06 | E10: 245.04
B11: Goodwill | C11: 9153.15 | D11: 9153.15 | E11: 9153.15
B12: Other intangible assets | C12: 37.84 | D12: 7.57 | E12: 4.91
B13: Right-of-use assets | C13: 960.73 | D13: 810.77 | E13: 885.54
B14: Investments accounted for using equity method | C14: 0 | D14: 0 | E14: 0
B15: Financial Assets
B16: Investments | C16: 0 | D16: 25 | E16: 155.88
B17: Other | C17: 2385.68 | D17: 54.88 | E17: 4429.39
B18: Other non-current assets | C18: 685.58 | D18: 319.55 | E18: 8.15
B19: Total non-current assets | C19: 13490.55 | D19: 10539.98 | E19: 14882.06
B21: Current assets
B22: Inventories | C22: 14.72 | D22: 17 | E22: 26.03
B23: Financial Assets
B24: Investments | C24: 145.92 | D24: 257.63 | E24: 0
B25: Trade receivables | C25: 1170.59 | D25: 1470.26 | E25: 2364.95
B26: Cash and cash equivalents | C26: 842.96 | D26: 1264.4 | E26: 1847.43
B27: Bank balances other than above | C27: 1687.75 | D27: 3753.08 | E27: 34.02
B28: Loans | C28: 0 | D28: 260 | E28: 300
B29: Other | C29: 2293.56 | D29: 4181.15 | E29: 3730.6
B30: Current tax assets (net) | C30: 307.85 | D30: 241.51 | E30: 421.38
B31: Other current assets | C31: 558.28 | D31: 1101.21 | E31: 1441.21
B32: Total current assets | C32: 7021.63 | D32: 12546.24 | E32: 10165.62
B34: Total assets | C34: 20512.18 | D34: 23086.22 | E34: 25047.68
B36: EQUITY AND LIABILITIES
B37: Equity share capital | C37: 5.18 | D37: 6.36 | E37: 6362.5
B38: Instruments entirely equity in nature | C38: 577.26 | D38: 595.24 | E38: 0
B39: Other equity | C39: 12279.33 | D39: 14310.91 | E39: 8880.61
B40: Non-controlling interests | C40: 0 | D40: 0 | E40: 0
B41: Total equity | C41: 12861.77 | D41: 14912.51 | E41: 15243.11
B43: Non-current liabilities
B44: Financial Liabilities
B45: Lease liabilities | C45: 845.75 | D45: 732.37 | E45: 752.24
B46: Provisions | C46: 53.06 | D46: 84.81 | E46: 123.91
B47: Total non-current liabilities | C47: 898.81 | D47: 817.18 | E47: 876.15
...

Sheet Income Statement
B2: ='Control Sheet'!B2 -> Shiprocket
B3: Income Statement
B4: In INR million unless stated otherwise
B6: Particulars | C6: 2024 | D6: =C6+1 -> 2025 | E6: =D6+1 -> 2026
B8: INCOME
B9: Revenue from Operations | C9: 13159.76 | D9: 16320.12 | E9: 20241.41
B10: Other income | C10: 418.57 | D10: 428.09 | E10: 532.8
B11: Total income (I) | C11: 13578.33 | D11: 16748.21 | E11: 20774.21
B13: EXPENSES
B14: Cost of Merchant Solutions | C14: 10070.37 | D14: 12129.31 | E14: 14941.29
B15: Purchase of traded goods | C15: 55.67 | D15: 79.67 | E15: 217.69
B16: Changes in inventories of traded goods | C16: -2.59 | D16: -2.28 | E16: -9.03
B17: Employee benefits expense | C17: 4307.91 | D17: 3149.16 | E17: 3794.77
B18: Finance cost | C18: 233.14 | D18: 220.69 | E18: 263.93
B19: Depreciation and amortisation expense | C19: 759.78 | D19: 352.2 | E19: 362.97
B20: Other expenses | C20: 1660.07 | D20: 1563.95 | E20: 1962.02
B21: Total Expenses (II) | C21: 17086.35 | D21: 17492.7 | E21: 21533.64
B22: Restated Loss before exceptional items, share of loss of an associate and tax (III=I-II) | C22: -3508.02 | D22: -744.49 | E22: -759.43
B23: Exceptional items | C23: -2443.79 | D23: 0 | E23: -33.02
B24: Restated Loss before share of loss of an associate and tax | C24: -5951.81 | D24: -744.49 | E24: -792.45
B25: Share of loss of an associate | C25: 0 | D25: 0 | E25: 0
B26: Restated Loss before tax | C26: -5951.81 | D26: -744.49 | E26: -792.45
B28: TAX EXPENSES
B29: Current tax | C29: 0 | D29: 0 | E29: 0
B30: Deferred tax | C30: 0 | D30: 0 | E30: 0
B31: Total Tax Expense (VIII) | C31: 0 | D31: 0 | E31: 0
B32: Restated Loss for the year (IX=VI-VIII) | C32: -5951.81 | D32: -744.49 | E32: -792.45
B36: OTHER COMPREHENSIVE INCOME
B37: (a) Items that will not be reclassified to profit or loss in subsequent years:
B38: (i) Remeasurement gain/(loss) on defined benefit plans | C38: 5.31 | D38: -22.72 | E38: -6.85
B39: (ii) Gain on sale of equity & preference instruments carried at FVTOCI | C39: 0.5 | D39: 0 | E39: 0
B40: (iii) Changes in fair value of equity & preference instruments carried at FVTOCI | C40: -52.98 | D40: 0 | E40: 0
B41: (iv) Income tax relating to above | C41: 0 | D41: 0 | E41: 0
B42: (b) Items that will be reclassified to profit or loss in subsequent years:
B43: (i) Exchange differences on translating the financial statements of foreign operations | C43: 0.7 | D43: 0.58 | E43: 6.13
B44: (ii) Income tax relating to above | C44: 0 | D44: 0 | E44: 0
B45: Total Restated Other Comprehensive Loss for the year (X=a+b) | C45: -46.47 | D45: -22.14 | E45: -0.72
B46: Restated Total comprehensive loss (XI=X+IX) | C46: -5998.28 | D46: -766.63 | E46: -793.17
B47: ATTRIBUTION
B48: Restated Loss attributable to: Equity holders of the parent | C48: -5924.13 | D48: -744.49 | E48: -792.45
...

Sheet Cash Flow Statement
B2: ='Control Sheet'!B2 -> Shiprocket
B3: Cash Flow Statement
B4: In INR million unless stated otherwise
B6: Particulars | C6: 2024 | D6: =C6+1 -> 2025 | E6: =D6+1 -> 2026
B8: A) Operating Activities
B9: Restated Loss before tax | C9: -5951.81 | D9: -744.49 | E9: -792.45
B10: Adjustments to reconcile Restated Loss before tax to net cash flows:
B11: Depreciation of Property, plant and equipment | C11: 217.38 | D11: 120.13 | E11: 100.71
B12: Impairment in value of Goodwill | C12: 1767.42 | D12: 0 | E12: 0
B13: Amortisation of Intangible assets | C13: 307.3 | D13: 30.27 | E13: 7.97
B14: Impairment of intangible assets | C14: 753.15 | D14: 0 | E14: 0
B15: Depreciation of right-of-use assets | C15: 235.1 | D15: 201.8 | E15: 254.29
B16: Provision for Doubtful Debts (net) | C16: 197.73 | D16: 100.68 | E16: 53.89
B17: Provision for Doubtful Recoverables (net) | C17: 117.42 | D17: 18.04 | E17: -8.73
B18: Recoverables written off | C18: 4.26 | D18: 0 | E18: 0
B19: Provision for impairment of Amount Recoverable | C19: 15.56 | D19: 0 | E19: 0
B20: Net foreign exchange differences (unrealised) | C20: 4.08 | D20: 0.72 | E20: 2.49
B21: Share based payment expense | C21: 1926.46 | D21: 912.77 | E21: 1123.43
B22: Profit on sale of subsidiary | C22: -92.34 | D22: 0 | E22: 0
... B35: Operating cash flow before working capital changes | C35: -661.94 | D35: 502.6 | E35: 484.98
B36: Movements in working capital:
B37: (Increase) in Inventories | C37: -2.59 | D37: -2.28 | E37: -9.03
B38: (Increase) in Trade receivables | C38: -460.8 | D38: -400.35 | E38: -948.57
B39: (Increase) in Other financial assets | C39: -319.36 | D39: -266.55 | E39: -317.97
B40: (Increase) in Other Assets | C40: -947.47 | D40: -167.42 | E40: -29.93
B41: Increase in Trade Payables | C41: 35.88 | D41: 273.58 | E41: 431.24
B42: Increase/(Decrease) in Other financial liabilities | C42: -79.13 | D42: -222.24 | E42: 502.99
B43: Increase in Other liabilities | C43: 235.69 | D43: 187.56 | E43: 517.86
B44: Increase in Provisions | C44: 24.22 | D44: 33.43 | E44: 73.8
B45: Cash flow from/(used in) Operations | C45: -2175.5 | D45: -61.67 | E45: 705.37
B46: Income taxes paid (net of refund) | C46: 15.58 | D46: 80.64 | E46: -179
B47: Net cash flows from/(used in) Operating activities (A) | C47: -2159.92 | D47: 18.97 | E47: 526.37
B49: B) Investing Activities
B50: Purchase of property, plant and equipment (including other intangible assets and capital advances) | C50: -245.16 | D50: -65.78 | E50: -181.66
B51: Proceeds from sale of property, plant and equipment (including other intangible assets) | C51: 1.81 | D51: 0.31 | E51: 1.41
B52: Proceeds from sale of subsidiary | C52: 0.27 | D52: 0 | E52: 0
B53: Proceeds from sale of Other Investments | C53: 0.5 | D53: 0 | E53: 0
B54: Payment towards acquisition of Other Investments | C54: -5.99 | D54: -25 | E54: -130.88
B55: Proceeds from sale of Mutual Fund units | C55: 71.7 | D55: 0 | E55: 5544.06
B56: Investment in Loan to Others | C56: 0 | D56: -260 | E56: -650
...

Sheet Assumption
B2: ='Control Sheet'!B2 -> Shiprocket
B3: Assumption Sheet
B4: #VALUE! | F4: #VALUE!
B10: #VALUE!
F14: EBITDA Margin | G14: 26 | H14: =G14+1 -> 27 | I14: =H14+1 -> 28 | J14: =I14+1 -> 29 | K14: =J14+1 -> 30 | L14: =K14+1 -> 31
F15: Core (50 bps) | G15: 0.128 | H15: =G15+0.5% -> 0.133 | I15: =H15+0.5% -> 0.138 | J15: =I15+0.5% -> 0.143 | K15: =J15+0.5% -> 0.148 | L15: =K15+0.5% -> 0.153
B17: #VALUE! | F17: Emerging (1380 bps) | G17: -0.38 | H17: =G17+13.8% -> -0.242 | I17: =H17+13.8% -> -0.104 | J17: =I17+13.8% -> 0.034 | K17: =J17+13.8% -> 0.172 | L17: =K17+13.8% -> 0.31
F19: #VALUE!
B23: Segment | C23: Revenue | D23: YoY Growth
B24: Core | C24: 412 | D24: 0.22
B25: Emerging | C25: 180 | D25: 0.7
B26: Total | C26: =C24+C25 -> 592 | D26: 0.34 | F26: #VALUE!
B28: Management observation | C28: What it means | D28: Model assumption it can support
B29: Revenue +34% | C29: Strong growth | D29: Near-term revenue growth
B30: Core +22% | C30: Core remains strong | D30: Core revenue growth
B31: Emerging +70% | C31: Emerging is scaling rapidly | D31: Emerging revenue growth | F31: #VALUE!
B32: Emerging share 24% → 30% | C32: Mix shifting | D32: Segment mix
B33: Core EBITDA margin 12.8% | C33: Core profitable | D33: Core EBITDA margin
B34: Core margin +50 bps | C34: Core efficiency improving | D34: Gradual margin expansion
B35: Emerging EBITDA (38%) → (24%) | C35: Losses narrowing | D35: Emerging margin improvement
B36: EBITDA/transaction ₹0.22 → ₹1.45 | C36: Unit economics improving | D36: EBITDA/transaction / margin | F36: #VALUE!
B38: Shiprocket Revenue
B39: Business Segment | C39: Key Components | D39: Contribution
B40: Core Business | C40: Domestic shipping + shipping apps | D40: 0.695
B41: Emerging Business | C41: Omnichannel, cross-border, checkout & marketing | D41: 0.305
B54: Evolution Period
B55: Years | C55: Evolution
B56: 2011 | C56: Bigfoot Retail Solutions
B57: 2012 | C57: SmartStore / KartRocket
B58: 2017 | C58: Shiprocket launched
B59: Present | C59: Integrated e-commerce enablement platform
B61: Indian E-commerce Market (USD Billion)
B62: Year | C62: Valued
B63: 2021 | C63: 67
B64: =B63+1 -> 2022 | C64: 84
B65: =B64+1 -> 2023 | C65: 102
B66: =B65+1 -> 2024 | C66: 125
B67: =B66+1 -> 2025 | C67: 145
B68: =B67+1 -> 2026 | C68: 163
B69: 2030 | C69: 345
...
